Workbook

Sheet 05_Executive_Dashboard
B2: INDIAN POWER MARKET ANALYSIS — DAM vs RTM FINANCIAL MIS & WORKING CAPITAL DASHBOARD
B5: TOTAL TRADED VOLUME | E5: GROSS INVOICED REVENUE | H5: NET TRADING MARGIN | K5: PEAK LIQUIDITY DEFICIT
B6: ='03_Financial_MIS'!C6 -> 19.5 | E6: ='03_Financial_MIS'!D6 -> 14.230253 | H6: ='03_Financial_MIS'!F6 -> 9.15 | K6: ='04_Working_Capital'!L3 -> -12.407851
B7: DAM: 15.00 MUs | RTM: 4.50 MUs | E7: Wholesale Cost: ₹14.14 Cr | H7: Realized: 4.69 paise/kWh | K7: Financing Drag: ₹12.59 Lakhs
B31: PORTFOLIO FINANCIAL PERFORMANCE & TREASURY RISK AUDIT
B32: Segment | D32: Client | F32: Volume (MUs) | G32: Revenue (₹ Cr) | H32: Power Cost (₹ Cr) | I32: Net Margin (₹ Lk) | J32: Realized Margin | K32: Settlement Cycle | L32: Treasury Working Capital Risk
B33: DAM | D33: UPPCL (State DISCOM) | F33: ='03_Financial_MIS'!C4 -> 15 | G33: ='03_Financial_MIS'!D4 -> 11.262135 | H33: ='03_Financial_MIS'!E4 -> 11.202135 | I33: ='03_Financial_MIS'!F4 -> 6 | J33: ='03_Financial_MIS'!G4 -> 4 | K33: T+45 Days | L33: High Deficit Drag (Requires Bank LC Discounting)
B34: RTM | D34: Tata Steel (Industrial C&I) | F34: ='03_Financial_MIS'!C5 -> 4.5 | G34: ='03_Financial_MIS'!D5 -> 2.9681179 | H34: ='03_Financial_MIS'!E5 -> 2.936618 | I34: ='03_Financial_MIS'!F5 -> 3.15 | J34: ='03_Financial_MIS'!G5 -> 7 | K34: T+15 Days | L34: Low Liquidity Drag (High Margin Contribution)
B35: Total | D35: Combined Portfolio | F35: ='03_Financial_MIS'!C6 -> 19.5 | G35: ='03_Financial_MIS'!D6 -> 14.230253 | H35: ='03_Financial_MIS'!E6 -> 14.138753 | I35: ='03_Financial_MIS'!F6 -> 9.15 | J35: ='03_Financial_MIS'!G6 -> 4.6923077 | K35: Weighted | L35: Net Deficit: -₹3.44 L after 9% Financing Cost

Sheet 01_Daily_Market_Data
A1: Delivery Date | B1: DAM Cleared Vol (MWh) | C1: DAM MCP (₹/MWh) | D1: DAM Price (₹/kWh) | E1: RTM Cleared Vol (MWh) | F1: RTM MCP (₹/MWh) | G1: RTM Price (₹/kWh) | H1: Price Spread (₹/kWh) | I1: Market Condition
A2: 26-09-2026 | B2: 146541.54 | C2: 4299.38 | D2: =C2/1000 -> 4.29938 | E2: 315357.94 | F2: 2028.85 | G2: =F2/1000 -> 2.02885 | H2: =G2-D2 -> -2.27053 | I2: =IF(H2>0, "RTM Premium (Deficit)", "DAM Premium (Surplus)") -> DAM Premium (Surplus)
A3: 27-09-2026 | B3: 169577.67 | C3: 2755.9 | D3: =C3/1000 -> 2.7559 | E3: 291110.76 | F3: 4045.77 | G3: =F3/1000 -> 4.04577 | H3: =G3-D3 -> 1.28987 | I3: =IF(H3>0, "RTM Premium (Deficit)", "DAM Premium (Surplus)") -> RTM Premium (Deficit)
A4: 28-09-2026 | B4: 203626.85 | C4: 5444.22 | D4: =C4/1000 -> 5.44422 | E4: 207550.47 | F4: 5966.91 | G4: =F4/1000 -> 5.96691 | H4: =G4-D4 -> 0.52269 | I4: =IF(H4>0, "RTM Premium (Deficit)", "DAM Premium (Surplus)") -> RTM Premium (Deficit)
A5: 29-09-2026 | B5: 179349.08 | C5: 7448.56 | D5: =C5/1000 -> 7.44856 | E5: 175660.52 | F5: 6388.59 | G5: =F5/1000 -> 6.38859 | H5: =G5-D5 -> -1.05997 | I5: =IF(H5>0, "RTM Premium (Deficit)", "DAM Premium (Surplus)") -> DAM Premium (Surplus)
A6: 30-09-2026 | B6: 184623.35 | C6: 7652.12 | D6: =C6/1000 -> 7.65212 | E6: 158982.55 | F6: 6931.1 | G6: =F6/1000 -> 6.9311 | H6: =G6-D6 -> -0.72102 | I6: =IF(H6>0, "RTM Premium (Deficit)", "DAM Premium (Surplus)") -> DAM Premium (Surplus)
A7: 01-10-2026 | B7: 165473.29 | C7: 7426.52 | D7: =C7/1000 -> 7.42652 | E7: 148551.91 | F7: 7134.52 | G7: =F7/1000 -> 7.13452 | H7: =G7-D7 -> -0.292 | I7: =IF(H7>0, "RTM Premium (Deficit)", "DAM Premium (Surplus)") -> DAM Premium (Surplus)
A8: 02-10-2026 | B8: 154080.61 | C8: 7169.79 | D8: =C8/1000 -> 7.16979 | E8: 139366.41 | F8: 7027.89 | G8: =F8/1000 -> 7.02789 | H8: =G8-D8 -> -0.1419 | I8: =IF(H8>0, "RTM Premium (Deficit)", "DAM Premium (Surplus)") -> DAM Premium (Surplus)
A9: 03-10-2026 | B9: 130727.18 | C9: 7209.2 | D9: =C9/1000 -> 7.2092 | E9: 143106.55 | F9: 7669.24 | G9: =F9/1000 -> 7.66924 | H9: =G9-D9 -> 0.46004 | I9: =IF(H9>0, "RTM Premium (Deficit)", "DAM Premium (Surplus)") -> RTM Premium (Deficit)
A10: 04-10-2026 | B10: 131123.46 | C10: 7064.7 | D10: =C10/1000 -> 7.0647 | E10: 139539 | F10: 7209.62 | G10: =F10/1000 -> 7.20962 | H10: =G10-D10 -> 0.14492 | I10: =IF(H10>0, "RTM Premium (Deficit)", "DAM Premium (Surplus)") -> RTM Premium (Deficit)
A11: 05-10-2026 | B11: 132980.61 | C11: 7599.52 | D11: =C11/1000 -> 7.59952 | E11: 129980.1 | F11: 8009.22 | G11: =F11/1000 -> 8.00922 | H11: =G11-D11 -> 0.4097 | I11: =IF(H11>0, "RTM Premium (Deficit)", "DAM Premium (Surplus)") -> RTM Premium (Deficit)
A12: 06-10-2026 | B12: 132191.93 | C12: 7764.29 | D12: =C12/1000 -> 7.76429 | E12: 132768.52 | F12: 7854.28 | G12: =F12/1000 -> 7.85428 | H12: =G12-D12 -> 0.08999 | I12: =IF(H12>0, "RTM Premium (Deficit)", "DAM Premium (Surplus)") -> RTM Premium (Deficit)
A13: 07-10-2026 | B13: 151808.29 | C13: 7993.4 | D13: =C13/1000 -> 7.9934 | E13: 141719.76 | F13: 7868.11 | G13: =F13/1000 -> 7.86811 | H13: =G13-D13 -> -0.12529 | I13: =IF(H13>0, "RTM Premium (Deficit)", "DAM Premium (Surplus)") -> DAM Premium (Surplus)
... A31: 25-10-2026 | B31: 160847.88 | C31: 3999.66 | D31: =C31/1000 -> 3.99966 | E31: 204945.35 | F31: 2774.37 | G31: =F31/1000 -> 2.77437 | H31: =G31-D31 -> -1.22529 | I31: =IF(H31>0, "RTM Premium (Deficit)", "DAM Premium (Surplus)") -> DAM Premium (Surplus)
A32: Average | B32: =AVERAGE(B2:B31) -> 148857.47 | C32: =AVERAGE(C2:C31) -> 7018.09 | D32: =AVERAGE(D2:D31) -> 7.01809 | E32: =AVERAGE(E2:E31) -> 183314.07 | F32: =AVERAGE(F2:F31) -> 6075.8177 | G32: =AVERAGE(G2:G31) -> 6.0758177 | H32: =AVERAGE(H2:H31) -> -0.94227233

Sheet 02_Trading_Ledger
A1: Transaction ID | B1: Delivery Date | C1: Market Segment | D1: Client Name | E1: Client Type | F1: Volume Traded (MWh) | G1: Exchange Buy Rate (₹/kWh) | H1: Open Access & Wheeling (₹/kWh) | I1: Trading Margin (₹/kWh) | J1: Billed Tariff (₹/kWh) | K1: Direct Power Cost (₹) | L1: Gross Invoiced Revenue (₹) | M1: Net Trading Margin (₹)
A2: TXN-DAM-001 | B2: ='01_Daily_Market_Data'!A2 -> 26-09-2026 | C2: DAM | D2: UPPCL | E2: DISCOM | F2: 500 | G2: ='01_Daily_Market_Data'!D2 -> 4.29938 | H2: 0.45 | I2: 0.04 | J2: =G2+H2+I2 -> 4.78938 | K2: =F2*1000*(G2+H2) -> 2374690 | L2: =F2*1000*J2 -> 2394690 | M2: =L2-K2 -> 20000
A3: TXN-DAM-002 | B3: ='01_Daily_Market_Data'!A3 -> 27-09-2026 | C3: DAM | D3: UPPCL | E3: DISCOM | F3: 500 | G3: ='01_Daily_Market_Data'!D3 -> 2.7559 | H3: 0.45 | I3: 0.04 | J3: =G3+H3+I3 -> 3.2459 | K3: =F3*1000*(G3+H3) -> 1602950 | L3: =F3*1000*J3 -> 1622950 | M3: =L3-K3 -> 20000
A4: TXN-DAM-003 | B4: ='01_Daily_Market_Data'!A4 -> 28-09-2026 | C4: DAM | D4: UPPCL | E4: DISCOM | F4: 500 | G4: ='01_Daily_Market_Data'!D4 -> 5.44422 | H4: 0.45 | I4: 0.04 | J4: =G4+H4+I4 -> 5.93422 | K4: =F4*1000*(G4+H4) -> 2947110 | L4: =F4*1000*J4 -> 2967110 | M4: =L4-K4 -> 20000
A5: TXN-DAM-004 | B5: ='01_Daily_Market_Data'!A5 -> 29-09-2026 | C5: DAM | D5: UPPCL | E5: DISCOM | F5: 500 | G5: ='01_Daily_Market_Data'!D5 -> 7.44856 | H5: 0.45 | I5: 0.04 | J5: =G5+H5+I5 -> 7.93856 | K5: =F5*1000*(G5+H5) -> 3949280 | L5: =F5*1000*J5 -> 3969280 | M5: =L5-K5 -> 20000
A6: TXN-DAM-005 | B6: ='01_Daily_Market_Data'!A6 -> 30-09-2026 | C6: DAM | D6: UPPCL | E6: DISCOM | F6: 500 | G6: ='01_Daily_Market_Data'!D6 -> 7.65212 | H6: 0.45 | I6: 0.04 | J6: =G6+H6+I6 -> 8.14212 | K6: =F6*1000*(G6+H6) -> 4051060 | L6: =F6*1000*J6 -> 4071060 | M6: =L6-K6 -> 20000
A7: TXN-DAM-006 | B7: ='01_Daily_Market_Data'!A7 -> 01-10-2026 | C7: DAM | D7: UPPCL | E7: DISCOM | F7: 500 | G7: ='01_Daily_Market_Data'!D7 -> 7.42652 | H7: 0.45 | I7: 0.04 | J7: =G7+H7+I7 -> 7.91652 | K7: =F7*1000*(G7+H7) -> 3938260 | L7: =F7*1000*J7 -> 3958260 | M7: =L7-K7 -> 20000
A8: TXN-DAM-007 | B8: ='01_Daily_Market_Data'!A8 -> 02-10-2026 | C8: DAM | D8: UPPCL | E8: DISCOM | F8: 500 | G8: ='01_Daily_Market_Data'!D8 -> 7.16979 | H8: 0.45 | I8: 0.04 | J8: =G8+H8+I8 -> 7.65979 | K8: =F8*1000*(G8+H8) -> 3809895 | L8: =F8*1000*J8 -> 3829895 | M8: =L8-K8 -> 20000
A9: TXN-DAM-008 | B9: ='01_Daily_Market_Data'!A9 -> 03-10-2026 | C9: DAM | D9: UPPCL | E9: DISCOM | F9: 500 | G9: ='01_Daily_Market_Data'!D9 -> 7.2092 | H9: 0.45 | I9: 0.04 | J9: =G9+H9+I9 -> 7.6992 | K9: =F9*1000*(G9+H9) -> 3829600 | L9: =F9*1000*J9 -> 3849600 | M9: =L9-K9 -> 20000
A10: TXN-DAM-009 | B10: ='01_Daily_Market_Data'!A10 -> 04-10-2026 | C10: DAM | D10: UPPCL | E10: DISCOM | F10: 500 | G10: ='01_Daily_Market_Data'!D10 -> 7.0647 | H10: 0.45 | I10: 0.04 | J10: =G10+H10+I10 -> 7.5547 | K10: =F10*1000*(G10+H10) -> 3757350 | L10: =F10*1000*J10 -> 3777350 | M10: =L10-K10 -> 20000
A11: TXN-DAM-010 | B11: ='01_Daily_Market_Data'!A11 -> 05-10-2026 | C11: DAM | D11: UPPCL | E11: DISCOM | F11: 500 | G11: ='01_Daily_Market_Data'!D11 -> 7.59952 | H11: 0.45 | I11: 0.04 | J11: =G11+H11+I11 -> 8.08952 | K11: =F11*1000*(G11+H11) -> 4024760 | L11: =F11*1000*J11 -> 4044760 | M11: =L11-K11 -> 20000
A12: TXN-DAM-011 | B12: ='01_Daily_Market_Data'!A12 -> 06-10-2026 | C12: DAM | D12: UPPCL | E12: DISCOM | F12: 500 | G12: ='01_Daily_Market_Data'!D12 -> 7.76429 | H12: 0.45 | I12: 0.04 | J12: =G12+H12+I12 -> 8.25429 | K12: =F12*1000*(G12+H12) -> 4107145 | L12: =F12*1000*J12 -> 4127145 | M12: =L12-K12 -> 20000
A13: TXN-DAM-012 | B13: ='01_Daily_Market_Data'!A13 -> 07-10-2026 | C13: DAM | D13: UPPCL | E13: DISCOM | F13: 500 | G13: ='01_Daily_Market_Data'!D13 -> 7.9934 | H13: 0.45 | I13: 0.04 | J13: =G13+H13+I13 -> 8.4834 | K13: =F13*1000*(G13+H13) -> 4221700 | L13: =F13*1000*J13 -> 4241700 | M13: =L13-K13 -> 20000
... A31: TXN-DAM-030 | B31: ='01_Daily_Market_Data'!A31 -> 25-10-2026 | C31: DAM | D31: UPPCL | E31: DISCOM | F31: 500 | G31: ='01_Daily_Market_Data'!D31 -> 3.99966 | H31: 0.45 | I31: 0.04 | J31: =G31+H31+I31 -> 4.48966 | K31: =F31*1000*(G31+H31) -> 2224830 | L31: =F31*1000*J31 -> 2244830 | M31: =L31-K31 -> 20000
A32: TXN-RTM-001 | B32: ='01_Daily_Market_Data'!A2 -> 26-09-2026 | C32: RTM | D32: Tata Steel | E32: C&I | F32: 150 | G32: ='01_Daily_Market_Data'!G2 -> 2.02885 | H32: 0.45 | I32: 0.07 | J32: =G32+H32+I32 -> 2.54885 | K32: =F32*1000*(G32+H32) -> 371827.5 | L32: =F32*1000*J32 -> 382327.5 | M32: =L32-K32 -> 10500
A33: TXN-RTM-002 | B33: ='01_Daily_Market_Data'!A3 -> 27-09-2026 | C33: RTM | D33: Tata Steel | E33: C&I | F33: 150 | G33: ='01_Daily_Market_Data'!G3 -> 4.04577 | H33: 0.45 | I33: 0.07 | J33: =G33+H33+I33 -> 4.56577 | K33: =F33*1000*(G33+H33) -> 674365.5 | L33: =F33*1000*J33 -> 684865.5 | M33: =L33-K33 -> 10500
A34: TXN-RTM-003 | B34: ='01_Daily_Market_Data'!A4 -> 28-09-2026 | C34: RTM | D34: Tata Steel | E34: C&I | F34: 150 | G34: ='01_Daily_Market_Data'!G4 -> 5.96691 | H34: 0.45 | I34: 0.07 | J34: =G34+H34+I34 -> 6.48691 | K34: =F34*1000*(G34+H34) -> 962536.5 | L34: =F34*1000*J34 -> 973036.5 | M34: =L34-K34 -> 10500
A35: TXN-RTM-004 | B35: ='01_Daily_Market_Data'!A5 -> 29-09-2026 | C35: RTM | D35: Tata Steel | E35: C&I | F35: 150 | G35: ='01_Daily_Market_Data'!G5 -> 6.38859 | H35: 0.45 | I35: 0.07 | J35: =G35+H35+I35 -> 6.90859 | K35: =F35*1000*(G35+H35) -> 1025788.5 | L35: =F35*1000*J35 -> 1036288.5 | M35: =L35-K35 -> 10500
A36: TXN-RTM-005 | B36: ='01_Daily_Market_Data'!A6 -> 30-09-2026 | C36: RTM | D36: Tata Steel | E36: C&I | F36: 150 | G36: ='01_Daily_Market_Data'!G6 -> 6.9311 | H36: 0.45 | I36: 0.07 | J36: =G36+H36+I36 -> 7.4511 | K36: =F36*1000*(G36+H36) -> 1107165 | L36: =F36*1000*J36 -> 1117665 | M36: =L36-K36 -> 10500
A37: TXN-RTM-006 | B37: ='01_Daily_Market_Data'!A7 -> 01-10-2026 | C37: RTM | D37: Tata Steel | E37: C&I | F37: 150 | G37: ='01_Daily_Market_Data'!G7 -> 7.13452 | H37: 0.45 | I37: 0.07 | J37: =G37+H37+I37 -> 7.65452 | K37: =F37*1000*(G37+H37) -> 1137678 | L37: =F37*1000*J37 -> 1148178 | M37: =L37-K37 -> 10500
A38: TXN-RTM-007 | B38: ='01_Daily_Market_Data'!A8 -> 02-10-2026 | C38: RTM | D38: Tata Steel | E38: C&I | F38: 150 | G38: ='01_Daily_Market_Data'!G8 -> 7.02789 | H38: 0.45 | I38: 0.07 | J38: =G38+H38+I38 -> 7.54789 | K38: =F38*1000*(G38+H38) -> 1121683.5 | L38: =F38*1000*J38 -> 1132183.5 | M38: =L38-K38 -> 10500
A39: TXN-RTM-008 | B39: ='01_Daily_Market_Data'!A9 -> 03-10-2026 | C39: RTM | D39: Tata Steel | E39: C&I | F39: 150 | G39: ='01_Daily_Market_Data'!G9 -> 7.66924 | H39: 0.45 | I39: 0.07 | J39: =G39+H39+I39 -> 8.18924 | K39: =F39*1000*(G39+H39) -> 1217886 | L39: =F39*1000*J39 -> 1228386 | M39: =L39-K39 -> 10500
A40: TXN-RTM-009 | B40: ='01_Daily_Market_Data'!A10 -> 04-10-2026 | C40: RTM | D40: Tata Steel | E40: C&I | F40: 150 | G40: ='01_Daily_Market_Data'!G10 -> 7.20962 | H40: 0.45 | I40: 0.07 | J40: =G40+H40+I40 -> 7.72962 | K40: =F40*1000*(G40+H40) -> 1148943 | L40: =F40*1000*J40 -> 1159443 | M40: =L40-K40 -> 10500
A41: TXN-RTM-010 | B41: ='01_Daily_Market_Data'!A11 -> 05-10-2026 | C41: RTM | D41: Tata Steel | E41: C&I | F41: 150 | G41: ='01_Daily_Market_Data'!G11 -> 8.00922 | H41: 0.45 | I41: 0.07 | J41: =G41+H41+I41 -> 8.52922 | K41: =F41*1000*(G41+H41) -> 1268883 | L41: =F41*1000*J41 -> 1279383 | M41: =L41-K41 -> 10500
A42: TXN-RTM-011 | B42: ='01_Daily_Market_Data'!A12 -> 06-10-2026 | C42: RTM | D42: Tata Steel | E42: C&I | F42: 150 | G42: ='01_Daily_Market_Data'!G12 -> 7.85428 | H42: 0.45 | I42: 0.07 | J42: =G42+H42+I42 -> 8.37428 | K42: =F42*1000*(G42+H42) -> 1245642 | L42: =F42*1000*J42 -> 1256142 | M42: =L42-K42 -> 10500
A43: TXN-RTM-012 | B43: ='01_Daily_Market_Data'!A13 -> 07-10-2026 | C43: RTM | D43: Tata Steel | E43: C&I | F43: 150 | G43: ='01_Daily_Market_Data'!G13 -> 7.86811 | H43: 0.45 | I43: 0.07 | J43: =G43+H43+I43 -> 8.38811 | K43: =F43*1000*(G43+H43) -> 1247716.5 | L43: =F43*1000*J43 -> 1258216.5 | M43: =L43-K43 -> 10500
... A61: TXN-RTM-030 | B61: ='01_Daily_Market_Data'!A31 -> 25-10-2026 | C61: RTM | D61: Tata Steel | E61: C&I | F61: 150 | G61: ='01_Daily_Market_Data'!G31 -> 2.77437 | H61: 0.45 | I61: 0.07 | J61: =G61+H61+I61 -> 3.29437 | K61: =F61*1000*(G61+H61) -> 483655.5 | L61: =F61*1000*J61 -> 494155.5 | M61: =L61-K61 -> 10500

Sheet 03_Financial_MIS
A2: TABLE 1: SEGMENT & CLIENT-WISE PROFITABILITY REPORT
A3: Segment | B3: Client | C3: Volume (MUs) | D3: Revenue (₹ Cr) | E3: Power Cost (₹ Cr) | F3: Net Margin (₹ Lakhs) | G3: Realized Margin (p/kWh)
A4: DAM | B4: UPPCL | C4: =SUMIF('02_Trading_Ledger'!C2:C61, "DAM", '02_Trading_Ledger'!F2:F61)/1000 -> 15 | D4: =SUMIF('02_Trading_Ledger'!C2:C61, "DAM", '02_Trading_Ledger'!L2:L61)/10000000 -> 11.262135 | E4: =SUMIF('02_Trading_Ledger'!C2:C61, "DAM", '02_Trading_Ledger'!K2:K61)/10000000 -> 11.202135 | F4: =SUMIF('02_Trading_Ledger'!C2:C61, "DAM", '02_Trading_Ledger'!M2:M61)/100000 -> 6 | G4: =(F4*100000)/(C4*1000000)*100 -> 4
A5: RTM | B5: Tata Steel | C5: =SUMIF('02_Trading_Ledger'!C2:C61, "RTM", '02_Trading_Ledger'!F2:F61)/1000 -> 4.5 | D5: =SUMIF('02_Trading_Ledger'!C2:C61, "RTM", '02_Trading_Ledger'!L2:L61)/10000000 -> 2.9681179 | E5: =SUMIF('02_Trading_Ledger'!C2:C61, "RTM", '02_Trading_Ledger'!K2:K61)/10000000 -> 2.936618 | F5: =SUMIF('02_Trading_Ledger'!C2:C61, "RTM", '02_Trading_Ledger'!M2:M61)/100000 -> 3.15 | G5: =(F5*100000)/(C5*1000000)*100 -> 7
A6: Total Portfolio | B6: — | C6: =C4+C5 -> 19.5 | D6: =D4+D5 -> 14.230253 | E6: =E4+E5 -> 14.138753 | F6: =F4+F5 -> 9.15 | G6: =(F6*100000)/(C6*1000000)*100 -> 4.6923077
A9: TABLE 2: BUDGET VS ACTUAL VARIANCE ANALYSIS
A10: Metric | B10: Budget Target | C10: Actual Cleared | D10: Variance (Abs) | E10: Variance (%) | F10: Management Commentary
A11: Traded Volume (MUs) | B11: 22 | C11: =C6 -> 19.5 | D11: =C11-B11 -> -2.5 | E11: =D11/B11 -> -0.11363636 | F11: Discom off-take curtailed due to high hydro generation.
A12: Avg Exchange MCP (₹/kWh) | B12: 5.5 | C12: ='01_Daily_Market_Data'!D32 -> 7.01809 | D12: =C12-B12 -> 1.51809 | E12: =D12/B12 -> 0.27601636 | F12: Spot MCP elevated due to seasonal evening peak demand.
A13: Gross Revenue (₹ Cr) | B13: 15 | C13: =D6 -> 14.230253 | D13: =C13-B13 -> -0.76974705 | E13: =D13/B13 -> -0.05131647 | F13: Lower volume partially offset by higher per-unit cleared tariff.
A14: Net Trading Margin (₹ Lakhs) | B14: 10.5 | C14: =F6 -> 9.15 | D14: =C14-B14 -> -1.35 | E14: =D14/B14 -> -0.12857143 | F14: Margin shortfall driven by 2.50 MU lower Discom volume.

Sheet 04_Working_Capital
A1: Day # | B1: Timeline Date | C1: Exchange Outflow (T+1) (₹) | D1: C&I Inflow (T+15) (₹) | E1: DISCOM Inflow (T+45) (₹) | F1: Total Cash Inflow (₹) | G1: Net Daily Cash Flow (₹) | H1: Cumulative Cash Position (₹ Cr) | I1: Daily Interest Cost @ 9% (₹)
A2: 1 | B2: ='01_Daily_Market_Data'!A2 -> 26-09-2026 | C2: 0 | D2: 0 | E2: 0 | F2: =D2+E2 -> 0 | G2: =F2-C2 -> 0 | H2: =G2/10000000 -> 0 | I2: =IF(H2<0, (-H2*10000000)*0.09/365, 0) -> 0
A3: 2 | B3: =B2+1 -> 46292 | C3: ='02_Trading_Ledger'!K2+'02_Trading_Ledger'!K32 -> 2746517.5 | D3: 0 | E3: 0 | F3: =D3+E3 -> 0 | G3: =F3-C3 -> -2746517.5 | H3: =H2+(G3/10000000) -> -0.27465175 | I3: =IF(H3<0, (-H3*10000000)*0.09/365, 0) -> 677.22349 | K3: Peak Liquidity Deficit (₹ Cr) | L3: =MIN(H2:H61) -> -12.407851
A4: 3 | B4: =B3+1 -> 46293 | C4: ='02_Trading_Ledger'!K3+'02_Trading_Ledger'!K33 -> 2277315.5 | D4: 0 | E4: 0 | F4: =D4+E4 -> 0 | G4: =F4-C4 -> -2277315.5 | H4: =H3+(G4/10000000) -> -0.5023833 | I4: =IF(H4<0, (-H4*10000000)*0.09/365, 0) -> 1238.7533 | K4: Day of Peak Deficit | L4: =MATCH(L3, H2:H61, 0) -> 31
A5: 4 | B5: =B4+1 -> 46294 | C5: ='02_Trading_Ledger'!K4+'02_Trading_Ledger'!K34 -> 3909646.5 | D5: 0 | E5: 0 | F5: =D5+E5 -> 0 | G5: =F5-C5 -> -3909646.5 | H5: =H4+(G5/10000000) -> -0.89334795 | I5: =IF(H5<0, (-H5*10000000)*0.09/365, 0) -> 2202.7758 | K5: Working Capital Limit Required (₹ Cr) | L5: =-L3*1.1 -> 13.648636
A6: 5 | B6: =B5+1 -> 46295 | C6: ='02_Trading_Ledger'!K5+'02_Trading_Ledger'!K35 -> 4975068.5 | D6: 0 | E6: 0 | F6: =D6+E6 -> 0 | G6: =F6-C6 -> -4975068.5 | H6: =H5+(G6/10000000) -> -1.3908548 | I6: =IF(H6<0, (-H6*10000000)*0.09/365, 0) -> 3429.505 | K6: Total Financing Cost Drag (₹ Lakhs) | L6: =SUM(I2:I61)/100000 -> 12.227314
A7: 6 | B7: =B6+1 -> 46296 | C7: ='02_Trading_Ledger'!K6+'02_Trading_Ledger'!K36 -> 5158225 | D7: 0 | E7: 0 | F7: =D7+E7 -> 0 | G7: =F7-C7 -> -5158225 | H7: =H6+(G7/10000000) -> -1.9066773 | I7: =IF(H7<0, (-H7*10000000)*0.09/365, 0) -> 4701.3961 | K7: Net Trade Profitability after Interest | L7: ='03_Financial_MIS'!F6-L6 -> -3.0773136
A8: 7 | B8: =B7+1 -> 46297 | C8: ='02_Trading_Ledger'!K7+'02_Trading_Ledger'!K37 -> 5075938 | D8: 0 | E8: 0 | F8: =D8+E8 -> 0 | G8: =F8-C8 -> -5075938 | H8: =H7+(G8/10000000) -> -2.4142711 | I8: =IF(H8<0, (-H8*10000000)*0.09/365, 0) -> 5952.9972
A9: 8 | B9: =B8+1 -> 46298 | C9: ='02_Trading_Ledger'!K8+'02_Trading_Ledger'!K38 -> 4931578.5 | D9: 0 | E9: 0 | F9: =D9+E9 -> 0 | G9: =F9-C9 -> -4931578.5 | H9: =H8+(G9/10000000) -> -2.9074289 | I9: =IF(H9<0, (-H9*10000000)*0.09/365, 0) -> 7169.0029
A10: 9 | B10: =B9+1 -> 46299 | C10: ='02_Trading_Ledger'!K9+'02_Trading_Ledger'!K39 -> 5047486 | D10: 0 | E10: 0 | F10: =D10+E10 -> 0 | G10: =F10-C10 -> -5047486 | H10: =H9+(G10/10000000) -> -3.4121776 | I10: =IF(H10<0, (-H10*10000000)*0.09/365, 0) -> 8413.5885
A11: 10 | B11: =B10+1 -> 46300 | C11: ='02_Trading_Ledger'!K10+'02_Trading_Ledger'!K40 -> 4906293 | D11: 0 | E11: 0 | F11: =D11+E11 -> 0 | G11: =F11-C11 -> -4906293 | H11: =H10+(G11/10000000) -> -3.9028069 | I11: =IF(H11<0, (-H11*10000000)*0.09/365, 0) -> 9623.3594
A12: 11 | B12: =B11+1 -> 46301 | C12: ='02_Trading_Ledger'!K11+'02_Trading_Ledger'!K41 -> 5293643 | D12: 0 | E12: 0 | F12: =D12+E12 -> 0 | G12: =F12-C12 -> -5293643 | H12: =H11+(G12/10000000) -> -4.4321712 | I12: =IF(H12<0, (-H12*10000000)*0.09/365, 0) -> 10928.641
A13: 12 | B13: =B12+1 -> 46302 | C13: ='02_Trading_Ledger'!K12+'02_Trading_Ledger'!K42 -> 5352787 | D13: 0 | E13: 0 | F13: =D13+E13 -> 0 | G13: =F13-C13 -> -5352787 | H13: =H12+(G13/10000000) -> -4.9674499 | I13: =IF(H13<0, (-H13*10000000)*0.09/365, 0) -> 12248.506
A14: 13 | B14: =B13+1 -> 46303 | C14: ='02_Trading_Ledger'!K13+'02_Trading_Ledger'!K43 -> 5469416.5 | D14: 0 | E14: 0 | F14: =D14+E14 -> 0 | G14: =F14-C14 -> -5469416.5 | H14: =H13+(G14/10000000) -> -5.5143915 | I14: =IF(H14<0, (-H14*10000000)*0.09/365, 0) -> 13597.13
A15: 14 | B15: =B14+1 -> 46304 | C15: ='02_Trading_Ledger'!K14+'02_Trading_Ledger'!K44 -> 5485225 | D15: 0 | E15: 0 | F15: =D15+E15 -> 0 | G15: =F15-C15 -> -5485225 | H15: =H14+(G15/10000000) -> -6.062914 | I15: =IF(H15<0, (-H15*10000000)*0.09/365, 0) -> 14949.651
A16: 15 | B16: =B15+1 -> 46305 | C16: ='02_Trading_Ledger'!K15+'02_Trading_Ledger'!K45 -> 5478457 | D16: 0 | E16: 0 | F16: =D16+E16 -> 0 | G16: =F16-C16 -> -5478457 | H16: =H15+(G16/10000000) -> -6.6107597 | I16: =IF(H16<0, (-H16*10000000)*0.09/365, 0) -> 16300.503
A17: 16 | B17: =B16+1 -> 46306 | C17: ='02_Trading_Ledger'!K16+'02_Trading_Ledger'!K46 -> 5405611.5 | D17: ='02_Trading_Ledger'!L32 -> 382327.5 | E17: 0 | F17: =D17+E17 -> 382327.5 | G17: =F17-C17 -> -5023284 | H17: =H16+(G17/10000000) -> -7.1130881 | I17: =IF(H17<0, (-H17*10000000)*0.09/365, 0) -> 17539.121
A18: 17 | B18: =B17+1 -> 46307 | C18: ='02_Trading_Ledger'!K17+'02_Trading_Ledger'!K47 -> 4991085 | D18: ='02_Trading_Ledger'!L33 -> 684865.5 | E18: 0 | F18: =D18+E18 -> 684865.5 | G18: =F18-C18 -> -4306219.5 | H18: =H17+(G18/10000000) -> -7.54371 | I18: =IF(H18<0, (-H18*10000000)*0.09/365, 0) -> 18600.929
A19: 18 | B19: =B18+1 -> 46308 | C19: ='02_Trading_Ledger'!K18+'02_Trading_Ledger'!K48 -> 5136763 | D19: ='02_Trading_Ledger'!L34 -> 973036.5 | E19: 0 | F19: =D19+E19 -> 973036.5 | G19: =F19-C19 -> -4163726.5 | H19: =H18+(G19/10000000) -> -7.9600827 | I19: =IF(H19<0, (-H19*10000000)*0.09/365, 0) -> 19627.601
A20: 19 | B20: =B19+1 -> 46309 | C20: ='02_Trading_Ledger'!K19+'02_Trading_Ledger'!K49 -> 5252410 | D20: ='02_Trading_Ledger'!L35 -> 1036288.5 | E20: 0 | F20: =D20+E20 -> 1036288.5 | G20: =F20-C20 -> -4216121.5 | H20: =H19+(G20/10000000) -> -8.3816948 | I20: =IF(H20<0, (-H20*10000000)*0.09/365, 0) -> 20667.193
A21: 20 | B21: =B20+1 -> 46310 | C21: ='02_Trading_Ledger'!K20+'02_Trading_Ledger'!K50 -> 5404819 | D21: ='02_Trading_Ledger'!L36 -> 1117665 | E21: 0 | F21: =D21+E21 -> 1117665 | G21: =F21-C21 -> -4287154 | H21: =H20+(G21/10000000) -> -8.8104102 | I21: =IF(H21<0, (-H21*10000000)*0.09/365, 0) -> 21724.299
A22: 21 | B22: =B21+1 -> 46311 | C22: ='02_Trading_Ledger'!K21+'02_Trading_Ledger'!K51 -> 5520382.5 | D22: ='02_Trading_Ledger'!L37 -> 1148178 | E22: 0 | F22: =D22+E22 -> 1148178 | G22: =F22-C22 -> -4372204.5 | H22: =H21+(G22/10000000) -> -9.2476307 | I22: =IF(H22<0, (-H22*10000000)*0.09/365, 0) -> 22802.377
A23: 22 | B23: =B22+1 -> 46312 | C23: ='02_Trading_Ledger'!K22+'02_Trading_Ledger'!K52 -> 5526777.5 | D23: ='02_Trading_Ledger'!L38 -> 1132183.5 | E23: 0 | F23: =D23+E23 -> 1132183.5 | G23: =F23-C23 -> -4394594 | H23: =H22+(G23/10000000) -> -9.6870901 | I23: =IF(H23<0, (-H23*10000000)*0.09/365, 0) -> 23885.976
A24: 23 | B24: =B23+1 -> 46313 | C24: ='02_Trading_Ledger'!K23+'02_Trading_Ledger'!K53 -> 5327204 | D24: ='02_Trading_Ledger'!L39 -> 1228386 | E24: 0 | F24: =D24+E24 -> 1228386 | G24: =F24-C24 -> -4098818 | H24: =H23+(G24/10000000) -> -10.096972 | I24: =IF(H24<0, (-H24*10000000)*0.09/365, 0) -> 24896.643
A25: 24 | B25: =B24+1 -> 46314 | C25: ='02_Trading_Ledger'!K24+'02_Trading_Ledger'!K54 -> 4712910.5 | D25: ='02_Trading_Ledger'!L40 -> 1159443 | E25: 0 | F25: =D25+E25 -> 1159443 | G25: =F25-C25 -> -3553467.5 | H25: =H24+(G25/10000000) -> -10.452319 | I25: =IF(H25<0, (-H25*10000000)*0.09/365, 0) -> 25772.841
A26: 25 | B26: =B25+1 -> 46315 | C26: ='02_Trading_Ledger'!K25+'02_Trading_Ledger'!K55 -> 4875543 | D26: ='02_Trading_Ledger'!L41 -> 1279383 | E26: 0 | F26: =D26+E26 -> 1279383 | G26: =F26-C26 -> -3596160 | H26: =H25+(G26/10000000) -> -10.811935 | I26: =IF(H26<0, (-H26*10000000)*0.09/365, 0) -> 26659.565
A27: 26 | B27: =B26+1 -> 46316 | C27: ='02_Trading_Ledger'!K26+'02_Trading_Ledger'!K56 -> 3982405 | D27: ='02_Trading_Ledger'!L42 -> 1256142 | E27: 0 | F27: =D27+E27 -> 1256142 | G27: =F27-C27 -> -2726263 | H27: =H26+(G27/10000000) -> -11.084561 | I27: =IF(H27<0, (-H27*10000000)*0.09/365, 0) -> 27331.794
A28: 27 | B28: =B27+1 -> 46317 | C28: ='02_Trading_Ledger'!K27+'02_Trading_Ledger'!K57 -> 3969420 | D28: ='02_Trading_Ledger'!L43 -> 1258216.5 | E28: 0 | F28: =D28+E28 -> 1258216.5 | G28: =F28-C28 -> -2711203.5 | H28: =H27+(G28/10000000) -> -11.355681 | I28: =IF(H28<0, (-H28*10000000)*0.09/365, 0) -> 28000.31
... A32: 31 | B32: =B31+1 -> 46321 | C32: ='02_Trading_Ledger'!K31+'02_Trading_Ledger'!K61 -> 2708485.5 | D32: ='02_Trading_Ledger'!L47 -> 968160 | E32: 0 | F32: =D32+E32 -> 968160 | G32: =F32-C32 -> -1740325.5 | H32: =H31+(G32/10000000) -> -12.407851 | I32: =IF(H32<0, (-H32*10000000)*0.09/365, 0) -> 30594.7
A33: 32 | B33: =B32+1 -> 46322 | C33: 0 | D33: ='02_Trading_Ledger'!L48 -> 979203 | E33: 0 | F33: =D33+E33 -> 979203 | G33: =F33-C33 -> 979203 | H33: =H32+(G33/10000000) -> -12.30993 | I33: =IF(H33<0, (-H33*10000000)*0.09/365, 0) -> 30353.253
A34: 33 | B34: =B33+1 -> 46323 | C34: 0 | D34: ='02_Trading_Ledger'!L49 -> 1196610 | E34: 0 | F34: =D34+E34 -> 1196610 | G34: =F34-C34 -> 1196610 | H34: =H33+(G34/10000000) -> -12.190269 | I34: =IF(H34<0, (-H34*10000000)*0.09/365, 0) -> 30058.198
A35: 34 | B35: =B34+1 -> 46324 | C35: 0 | D35: ='02_Trading_Ledger'!L50 -> 1345509 | E35: 0 | F35: =D35+E35 -> 1345509 | G35: =F35-C35 -> 1345509 | H35: =H34+(G35/10000000) -> -12.055718 | I35: =IF(H35<0, (-H35*10000000)*0.09/365, 0) -> 29726.429
A36: 35 | B36: =B35+1 -> 46325 | C36: 0 | D36: ='02_Trading_Ledger'!L51 -> 1267147.5 | E36: 0 | F36: =D36+E36 -> 1267147.5 | G36: =F36-C36 -> 1267147.5 | H36: =H35+(G36/10000000) -> -11.929004 | I36: =IF(H36<0, (-H36*10000000)*0.09/365, 0) -> 29413.982
A37: 36 | B37: =B36+1 -> 46326 | C37: 0 | D37: ='02_Trading_Ledger'!L52 -> 1221517.5 | E37: 0 | F37: =D37+E37 -> 1221517.5 | G37: =F37-C37 -> 1221517.5 | H37: =H36+(G37/10000000) -> -11.806852 | I37: =IF(H37<0, (-H37*10000000)*0.09/365, 0) -> 29112.786
A38: 37 | B38: =B37+1 -> 46327 | C38: 0 | D38: ='02_Trading_Ledger'!L53 -> 1090599 | E38: 0 | F38: =D38+E38 -> 1090599 | G38: =F38-C38 -> 1090599 | H38: =H37+(G38/10000000) -> -11.697792 | I38: =IF(H38<0, (-H38*10000000)*0.09/365, 0) -> 28843.871
A39: 38 | B39: =B38+1 -> 46328 | C39: 0 | D39: ='02_Trading_Ledger'!L54 -> 719710.5 | E39: 0 | F39: =D39+E39 -> 719710.5 | G39: =F39-C39 -> 719710.5 | H39: =H38+(G39/10000000) -> -11.625821 | I39: =IF(H39<0, (-H39*10000000)*0.09/365, 0) -> 28666.408
A40: 39 | B40: =B39+1 -> 46329 | C40: 0 | D40: ='02_Trading_Ledger'!L55 -> 738678 | E40: 0 | F40: =D40+E40 -> 738678 | G40: =F40-C40 -> 738678 | H40: =H39+(G40/10000000) -> -11.551953 | I40: =IF(H40<0, (-H40*10000000)*0.09/365, 0) -> 28484.268
A41: 40 | B41: =B40+1 -> 46330 | C41: 0 | D41: ='02_Trading_Ledger'!L56 -> 507555 | E41: 0 | F41: =D41+E41 -> 507555 | G41: =F41-C41 -> 507555 | H41: =H40+(G41/10000000) -> -11.501198 | I41: =IF(H41<0, (-H41*10000000)*0.09/365, 0) -> 28359.117
A42: 41 | B42: =B41+1 -> 46331 | C42: 0 | D42: ='02_Trading_Ledger'!L57 -> 694080 | E42: 0 | F42: =D42+E42 -> 694080 | G42: =F42-C42 -> 694080 | H42: =H41+(G42/10000000) -> -11.43179 | I42: =IF(H42<0, (-H42*10000000)*0.09/365, 0) -> 28187.974
A43: 42 | B43: =B42+1 -> 46332 | C43: 0 | D43: ='02_Trading_Ledger'!L58 -> 752203.5 | E43: 0 | F43: =D43+E43 -> 752203.5 | G43: =F43-C43 -> 752203.5 | H43: =H42+(G43/10000000) -> -11.356569 | I43: =IF(H43<0, (-H43*10000000)*0.09/365, 0) -> 28002.5
...
